Workbook

Sheet HUONG_DAN
B2: HỆ THỐNG 1800 CÂU TIẾNG ĐỨC | A0 → B2 trong 3 tháng
B3: Phương pháp: Lexical Approach (Lewis) + 10.000 Sentences / AJATT (i+1) + Mass Sentences (Glossika SRS)
B6: CÁC TAB TRONG FILE
B7: SETTINGS | C7: Nơi duy nhất bạn chỉnh tham số: ngày bắt đầu, số câu/ngày, số ngày đệm (lag), khoảng cách ôn SRS. Mọi tab khác tự tính lại theo đây.
B8: SENTENCES | C8: 1800 dòng câu. Mỗi dòng: câu Đức, phiên âm, nghĩa Việt, chủ đề, loại câu, điểm ngữ pháp, từ mới. Đây là nơi bạn TICK ngày học và ngày ôn.
B9: VOCAB | C9: Chú thích từng từ/cụm từ, gắn với đúng ID câu mà nó xuất hiện. Lọc được theo loại từ, chủ đề, cấp độ.
B10: DASHBOARD | C10: Bảng điều khiển: tiến độ hôm nay, số câu nợ, số ngày trễ, cảnh báo, 2 biểu đồ.
B11: DAILY_LOG | C11: Nhật ký 105 ngày (90 ngày kế hoạch + 15 ngày đệm). Tự đếm số câu học/ôn mỗi ngày, đánh dấu ngày nghỉ hoặc miss.
B13: CÁCH DÙNG HẰNG NGÀY
B14: Bước 1 | C14: Mở tab SENTENCES, bật AutoFilter ở cột 'Ngày thứ' chọn đúng ngày của hôm nay (xem DASHBOARD ô B6).
B15: Bước 2 | C15: Học 20 câu: đọc to câu Đức, soi phiên âm, hiểu nghĩa, liếc cột 'Điểm ngữ pháp'. Không học từ rời.
B16: Bước 3 | C16: Học xong câu nào, bấm vào ô 'Ngày học' của câu đó và nhấn Ctrl + ; (dấu chấm phẩy) để chèn ngày hôm nay.
B17: Bước 4 | C17: Lọc cột 'Trạng thái' = '◆ ÔN HÔM NAY' để biết câu nào tới hạn ôn. Ôn xong thì Ctrl + ; vào ô 'Ôn 1' (hoặc Ôn 2/3/4/5 nếu đã có).
B18: Bước 5 | C18: Cuối ngày liếc DASHBOARD. Đèn 🟢 là ổn, 🟡 là cần bù, 🔴 là đã vượt ngưỡng đệm 15 ngày.
B20: CƠ CHẾ SPACED REPETITION
B21: Khoảng lặp mặc định | C21: 1 ngày → 3 ngày → 7 ngày → 16 ngày → 35 ngày. Đủ 5 lần ôn thì câu được đánh dấu '✔ MASTER'.
B22: Ngày ôn kế tiếp | C22: Tự tính = ngày gần nhất bạn chạm vào câu đó + khoảng lặp tương ứng. Bạn không cần tính tay.
B23: Đổi khoảng lặp | C23: Sửa trực tiếp SETTINGS!B9:B13. Toàn bộ 1800 dòng tự cập nhật.
B25: CƠ CHẾ ĐỆM / LAG (ngày nghỉ)
B26: Nguyên tắc | C26: Hệ thống KHÔNG phạt bạn khi nghỉ. Nó chỉ cộng dồn 'số câu nợ' và quy ra 'số ngày trễ' = câu nợ / 20.
B27: Ngưỡng an toàn | C27: SETTINGS!B7 = 15 ngày. Trễ dưới 15 ngày vẫn kịp mốc 3 tháng ± sai số. Vượt 15 ngày thì DASHBOARD bật đèn đỏ.
B28: Bù như thế nào | C28: DASHBOARD ô 'Cần học mỗi ngày để kịp hạn chót' tự tính lại liều lượng mới. Cứ theo con số đó.
B30: PHIÊN ÂM IPA (International Phonetic Alphabet)
B31: Nguồn | C31: Toàn bộ 1800 câu được phiên âm bằng espeak-ng (giọng Đức chuẩn) rồi hiệu chỉnh lại theo quy ước Duden/Siebs.
B32: ˈ và ˌ | C32: Trọng âm chính và trọng âm phụ, đặt TRƯỚC âm tiết mang trọng âm: ˈɡuːtən, ˌʔaɪnə.
B33: ː | C33: Dấu kéo dài nguyên âm: Bahn [baːn] khác Bann [ban]. Đây là cặp đối lập có nghĩa trong tiếng Đức.
B34: ʔ | C34: Âm tắc thanh hầu, đứng trước nguyên âm đầu âm tiết mang trọng âm: ich [ʔɪç], eine [ˌʔaɪnə]. Người Việt hay bỏ âm này nên nghe bị dính chữ.
B35: ʁ | C35: R lưỡi gà, rung ở cuống họng, KHÔNG phải r đầu lưỡi như tiếng Việt: Rot [ʁoːt], Park [paʁk].
B36: ɐ̯ | C36: R bị nguyên âm hoá ở cuối âm tiết sau nguyên âm dài: sehr [zeːɐ̯], wir [viːɐ̯]. Nghe gần như một chữ a rất nhẹ.
B37: ɐ | C37: Đuôi -er không trọng âm: Mutter [ˈmʊtɐ], besser [ˈbɛsɐ]. Đừng đọc thành ơ-rờ.
B38: ə | C38: Schwa, nguyên âm giữa miệng, cực nhẹ: bitte [ˈbɪtə].
B39: ç và x | C39: Hai biến thể của ch: ç sau i/e/ä/ö/ü/phụ âm (ich [ʔɪç]), x sau a/o/u (Nacht [naxt]).
B40: ʃ | C40: Âm sh: schön [ʃøːn]. Chú ý st-/sp- đầu từ cũng đọc ʃ: Stadt [ʃtat], sprechen [ˈʃpʁɛçən].
B41: y ʏ ø œ | C41: Bốn nguyên âm tròn môi không có trong tiếng Việt: über [ˈʔyːbɐ], müssen [ˈmʏsən], schön [ʃøːn], möchte [ˈmœçtə].
B42: pf ts | C42: Phụ âm kép: Pferd [pfeːɐ̯t], Zeit [tsaɪt]. Chữ z luôn là ts.
B43: Lưu ý | C43: IPA mô tả cách phát âm chuẩn khi đọc rõ từng từ. Khi nói nhanh người Đức rút gọn nhiều, nên vẫn phải nghe audio gốc.
B45: CẤU TRÚC 90 NGÀY
B46: Ngày 1 đến 30 (600 câu) | C46: Trình độ A1 đến A2: chào hỏi, giới thiệu, gia đình, ăn uống, mua sắm, Modalverben, động từ tách, Dativ, Wechselpräpositionen, Perfekt.
B47: Ngày 31 đến 60 (600 câu) | C47: Trình độ B1: dass / weil / obwohl, mệnh đề thời gian, mệnh đề quan hệ đủ cách, Präteritum, Plusquamperfekt, Futur, bị động, Konjunktiv II, Genitiv, ngân hàng, hành chính, xin việc, nhà cửa, du lịch.
B48: Ngày 61 đến 90 (600 câu) | C48: Trình độ B2: lập luận và phản biện, Konjunktiv I và lời nói gián tiếp, cấu trúc phân từ, danh hóa, các dạng thay thế bị động, Modalpartikeln, môi trường, AI, kinh tế, chính trị, thành ngữ, lỗi thường gặp của người Việt, Redemittel luyện thi B2.
...

Sheet DASHBOARD
B2: DASHBOARD THEO DÕI TIẾN ĐỘ 1800 CÂU
B3: Mọi con số tự cập nhật theo ngày thật trên máy. Không có ô nào cần nhập tay ở tab này.
B5: THỜI GIAN | E5: ÔN TẬP HÔM NAY (SRS)
B6: Hôm nay | C6: =TODAY() -> 46301 | E6: Câu phải HỌC MỚI hôm nay | F6: =COUNTIF(SENTENCES!$T$3:$T$1802,"★ HỌC HÔM NAY") -> 20
B7: Hôm nay là NGÀY THỨ | C7: =MAX(0,TODAY()-SETTINGS!$C$3+1) -> 2 | E7: Câu tới hạn ÔN hôm nay | F7: =COUNTIF(SENTENCES!$T$3:$T$1802,"◆ ÔN HÔM NAY") -> 0
B8: Ngày bắt đầu | C8: =SETTINGS!$C$3 -> 46300 | E8: Câu TRỄ ÔN (cần xử lý ngay) | F8: =COUNTIF(SENTENCES!$T$3:$T$1802,"⚠ TRỄ ÔN") -> 0
B9: Mốc 3 tháng (ngày 90) | C9: =SETTINGS!$C$3+SETTINGS!$C$5-1 -> 46389 | E9: Câu TRỄ HỌC (chưa đụng tới) | F9: =COUNTIF(SENTENCES!$T$3:$T$1802,"⚠ TRỄ HỌC") -> 20
B10: Hạn chót có đệm 15 ngày | C10: =SETTINGS!$C$8 -> 46404 | E10: Câu đã MASTER (ôn đủ 5 lần) | F10: =COUNTIF(SENTENCES!$T$3:$T$1802,"✔ MASTER") -> 0
B11: Số ngày còn lại tới hạn chót | C11: =MAX(0,SETTINGS!$C$8-TODAY()) -> 103 | E11: Tổng việc hôm nay | F11: =$F$6+$F$7+$F$8+$F$9 -> 40
B13: KHỐI LƯỢNG | E13: KỶ LUẬT & CHẤT LƯỢNG
B14: Mục tiêu tổng (câu) | C14: =SETTINGS!$C$6 -> 1800 | E14: Số ngày đã học ít nhất 1 câu | F14: =SUMPRODUCT(--(DAILY_LOG!$E$3:$E$107>0)) -> 0
B15: Số câu đã có nội dung trong file | C15: =COUNTA(SENTENCES!$H$3:$H$1802) -> 1800 | E15: Số ngày NGHỈ / MISS đã qua | F15: =COUNTIF(DAILY_LOG!$K$3:$K$107,"✖ Nghỉ / Miss") -> 2
B16: ĐÃ HỌC (câu) | C16: =COUNTIFS(SENTENCES!$L$3:$L$1802,">0") -> 0 | E16: Số ngày đạt đủ 20 câu | F16: =COUNTIF(DAILY_LOG!$K$3:$K$107,"✔ Đủ chỉ tiêu") -> 0
B17: Kế hoạch phải xong tới hôm nay | C17: =MIN(MAX(0,(TODAY()-SETTINGS!$C$3+1))*SETTINGS!$C$4,SETTINGS!$C$6) -> 40 | E17: Trung bình câu mới / ngày đã qua | F17: =IF($F$14=0,0,ROUND($C$16/$F$14,1)) -> 0
B18: Câu đang NỢ | C18: =MAX(0,$C$17-$C$16) -> 40 | E18: Tổng lượt ôn đã thực hiện | F18: =SUM(SENTENCES!$R$3:$R$1802) -> 0
B19: Quy ra SỐ NGÀY TRỄ | C19: =ROUND($C$18/SETTINGS!$C$4,1) -> 2 | E19: Số câu A1 đã học | F19: =COUNTIFS(SENTENCES!$D$3:$D$1802,"A1",SENTENCES!$L$3:$L$1802,">0") -> 0
B20: % hoàn thành | C20: =IF(SETTINGS!$C$6=0,0,$C$16/SETTINGS!$C$6) -> 0 | E20: Số câu A2 đã học | F20: =COUNTIFS(SENTENCES!$D$3:$D$1802,"A2",SENTENCES!$L$3:$L$1802,">0") -> 0
B21: Cần học mỗi ngày để kịp hạn chót | C21: =IF(MAX(1,SETTINGS!$C$8-TODAY())=0,0,ROUNDUP(MAX(0,SETTINGS!$C$6-$C$16)/MAX(1,SETTINGS!$C$8-TODAY()),0)) -> 18 | E21: Số từ vựng đã mở khoá | F21: =COUNTIFS(VOCAB!$G$3:$G$2205,"<="&MAX(0,TODAY()-SETTINGS!$C$3+1)) -> 70
B23: =IF($C$19>SETTINGS!$C$7,"🔴 NGUY HIỂM: đã trễ "&TEXT($C$19,"0.0")&" ngày, vượt ngưỡng đệm "&SETTINGS!$C$7&" ngày. Phải học "&$C$21&" câu/ngày mới kịp hạn chót.",IF($C$19>5,"🟡 CẦN BÙ: đang trễ "&TEXT($C$19,"0.0")&" ngày. Nâng lên "&$C$21&" câu/ngày trong vài hôm là về lại đúng nhịp.",IF($C$16=0,"⚪ CHƯA BẮT ĐẦU: tick ngày học đầu tiên ở tab SENTENCES để hệ thống chạy.","🟢 ĐANG ĐÚNG NHỊP: trễ "&TEXT($C$19,"0.0")&" ngày, vẫn trong vùng an toàn. Giữ "&SETTINGS!$C$4&" câu/ngày."))) -> ⚪ CHƯA BẮT ĐẦU: tick ngày học đầu tiên ở tab SENTENCES để hệ thống chạy.
B26: BIỂU ĐỒ 1 - Đường tiến độ: kế hoạch lũy kế (xám) so với thực tế bạn đã học (xanh). Khoảng cách giữa 2 đường chính là số câu đang nợ.
B53: BIỂU ĐỒ 2 - Cột hoạt động mỗi ngày: câu học mới và lượt ôn. Cột trống = ngày nghỉ / miss.

Sheet SETTINGS
B2: BẢNG THAM SỐ (chỉ sửa ô màu vàng)
B3: Ngày bắt đầu học | C3: 46300 | D3: Ngày D1. Đổi ngày này thì toàn bộ lịch 1800 câu dịch theo.
B4: Số câu mới mỗi ngày | C4: 20 | D4: Liều lượng chuẩn của phương pháp 10.000 câu.
B5: Số ngày kế hoạch | C5: 90 | D5: 3 tháng.
B6: Tổng số câu mục tiêu | C6: =C4*C5 -> 1800 | D6: Tự tính = số câu/ngày x số ngày.
B7: Số ngày đệm cho phép (lag) | C7: 15 | D7: Sai số bạn chấp nhận: nghỉ, bận, quên. Vượt mức này DASHBOARD báo đỏ.
B8: Hạn chót cuối cùng | C8: =C3+C5-1+C7 -> 46404 | D8: Ngày bắt đầu + 90 ngày + 15 ngày đệm.
B9: Khoảng ôn SRS lần 1 (ngày) | C9: 1 | D9: Ôn lần 1 sau 1 ngày kể từ ngày học.
B10: Khoảng ôn SRS lần 2 (ngày) | C10: 3
B11: Khoảng ôn SRS lần 3 (ngày) | C11: 7
B12: Khoảng ôn SRS lần 4 (ngày) | C12: 16
B13: Khoảng ôn SRS lần 5 (ngày) | C13: 35 | D13: Sau lần 5 câu được coi là MASTER.
B14: Ngày hôm nay (tự cập nhật) | C14: =TODAY() -> 46301 | D14: Lấy từ đồng hồ máy, tự đổi mỗi lần mở file.

Sheet SENTENCES
A1: 1800 CÂU CỐT LÕI | Tick ngày vào cột L–Q (ô vàng) bằng Ctrl + ;
A2: ID | B2: Ngày thứ | C2: Ngày dự kiến | D2: Cấp độ | E2: Chủ đề | F2: Loại câu | G2: Điểm ngữ pháp | H2: Câu tiếng Đức | I2: Phiên âm IPA (chuẩn Duden) | J2: Nghĩa tiếng Việt | K2: Từ mới trong câu | L2: Ngày học (Ctrl+;) | M2: Ôn 1 | N2: Ôn 2 | O2: Ôn 3 | P2: Ôn 4 | Q2: Ôn 5 | R2: Số lần ôn | S2: Ngày ôn kế tiếp | T2: Trạng thái | U2: Thành thạo
A3: S0001 | B3: 1 | C3: =SETTINGS!$C$3+$B3-1 -> 46300 | D3: A1 | E3: Chào hỏi & Lịch sự | F3: Câu cảm thán | G3: Cụm chào hỏi cố định | H3: Guten Morgen! | I3: [ˈɡuːtən ˈmɔʁɡən] | J3: Chào buổi sáng! | K3: der Morgen = buổi sáng; gut = tốt | R3: =COUNT($M3:$Q3) -> 0 | S3: =IF($L3="","",IF($R3>=5,"",MAX($L3:$Q3)+CHOOSE($R3+1,SETTINGS!$C$9,SETTINGS!$C$10,SETTINGS!$C$11,SETTINGS!$C$12,SETTINGS!$C$13))) | T3: =IF($H3="","(chưa có nội dung)",IF($L3="",IF($C3<TODAY(),"⚠ TRỄ HỌC",IF($C3=TODAY(),"★ HỌC HÔM NAY","• Chưa tới")),IF($R3>=5,"✔ MASTER",IF($S3<TODAY(),"⚠ TRỄ ÔN",IF($S3=TODAY(),"◆ ÔN HÔM NAY","✔ Đúng tiến độ"))))) -> ⚠ TRỄ HỌC | U3: =IF($H3="","",$R3/5) -> 0
A4: S0002 | B4: 1 | C4: =SETTINGS!$C$3+$B4-1 -> 46300 | D4: A1 | E4: Chào hỏi & Lịch sự | F4: Câu hỏi | G4: wie geht es + Dativ (Ihnen) | H4: Guten Tag, wie geht es Ihnen? | I4: [ˈɡuːtən ˈtaːk, viː ˈɡeːt ʔɛs ˈʔiːnən] | J4: Chào ông/bà, ông/bà khỏe không? | K4: der Tag = ngày; gehen = đi/diễn ra | R4: =COUNT($M4:$Q4) -> 0 | S4: =IF($L4="","",IF($R4>=5,"",MAX($L4:$Q4)+CHOOSE($R4+1,SETTINGS!$C$9,SETTINGS!$C$10,SETTINGS!$C$11,SETTINGS!$C$12,SETTINGS!$C$13))) | T4: =IF($H4="","(chưa có nội dung)",IF($L4="",IF($C4<TODAY(),"⚠ TRỄ HỌC",IF($C4=TODAY(),"★ HỌC HÔM NAY","• Chưa tới")),IF($R4>=5,"✔ MASTER",IF($S4<TODAY(),"⚠ TRỄ ÔN",IF($S4=TODAY(),"◆ ÔN HÔM NAY","✔ Đúng tiến độ"))))) -> ⚠ TRỄ HỌC | U4: =IF($H4="","",$R4/5) -> 0
A5: S0003 | B5: 1 | C5: =SETTINGS!$C$3+$B5-1 -> 46300 | D5: A1 | E5: Chào hỏi & Lịch sự | F5: Câu hỏi | G5: geht's = geht es (rút gọn), dir = Dativ của du | H5: Hallo, wie geht's dir? | I5: [ˈhaloː, viː ˈɡeːts ˈdiːɐ̯] | J5: Chào bạn, bạn khỏe không? | K5: dir = với bạn (Dativ) | R5: =COUNT($M5:$Q5) -> 0 | S5: =IF($L5="","",IF($R5>=5,"",MAX($L5:$Q5)+CHOOSE($R5+1,SETTINGS!$C$9,SETTINGS!$C$10,SETTINGS!$C$11,SETTINGS!$C$12,SETTINGS!$C$13))) | T5: =IF($H5="","(chưa có nội dung)",IF($L5="",IF($C5<TODAY(),"⚠ TRỄ HỌC",IF($C5=TODAY(),"★ HỌC HÔM NAY","• Chưa tới")),IF($R5>=5,"✔ MASTER",IF($S5<TODAY(),"⚠ TRỄ ÔN",IF($S5=TODAY(),"◆ ÔN HÔM NAY","✔ Đúng tiến độ"))))) -> ⚠ TRỄ HỌC | U5: =IF($H5="","",$R5/5) -> 0
A6: S0004 | B6: 1 | C6: =SETTINGS!$C$3+$B6-1 -> 46300 | D6: A1 | E6: Chào hỏi & Lịch sự | F6: Câu trả lời | G6: mir = Dativ của ich | H6: Mir geht es gut, danke. | I6: [miːɐ̯ ˈɡeːt ʔɛs ˈɡuːt, ˈdaŋkə] | J6: Tôi khỏe, cảm ơn. | K6: mir = với tôi (Dativ); danke = cảm ơn | R6: =COUNT($M6:$Q6) -> 0 | S6: =IF($L6="","",IF($R6>=5,"",MAX($L6:$Q6)+CHOOSE($R6+1,SETTINGS!$C$9,SETTINGS!$C$10,SETTINGS!$C$11,SETTINGS!$C$12,SETTINGS!$C$13))) | T6: =IF($H6="","(chưa có nội dung)",IF($L6="",IF($C6<TODAY(),"⚠ TRỄ HỌC",IF($C6=TODAY(),"★ HỌC HÔM NAY","• Chưa tới")),IF($R6>=5,"✔ MASTER",IF($S6<TODAY(),"⚠ TRỄ ÔN",IF($S6=TODAY(),"◆ ÔN HÔM NAY","✔ Đúng tiến độ"))))) -> ⚠ TRỄ HỌC | U6: =IF($H6="","",$R6/5) -> 0
A7: S0005 | B7: 1 | C7: =SETTINGS!$C$3+$B7-1 -> 46300 | D7: A1 | E7: Chào hỏi & Lịch sự | F7: Câu phủ định | G7: nicht đứng trước tính từ | H7: Es geht mir nicht so gut. | I7: [ʔɛs ˈɡeːt miːɐ̯ ˈnɪçt zoː ˈɡuːt] | J7: Tôi không được khỏe lắm. | K7: nicht = không; so = như thế | R7: =COUNT($M7:$Q7) -> 0 | S7: =IF($L7="","",IF($R7>=5,"",MAX($L7:$Q7)+CHOOSE($R7+1,SETTINGS!$C$9,SETTINGS!$C$10,SETTINGS!$C$11,SETTINGS!$C$12,SETTINGS!$C$13))) | T7: =IF($H7="","(chưa có nội dung)",IF($L7="",IF($C7<TODAY(),"⚠ TRỄ HỌC",IF($C7=TODAY(),"★ HỌC HÔM NAY","• Chưa tới")),IF($R7>=5,"✔ MASTER",IF($S7<TODAY(),"⚠ TRỄ ÔN",IF($S7=TODAY(),"◆ ÔN HÔM NAY","✔ Đúng tiến độ"))))) -> ⚠ TRỄ HỌC | U7: =IF($H7="","",$R7/5) -> 0
A8: S0006 | B8: 1 | C8: =SETTINGS!$C$3+$B8-1 -> 46300 | D8: A1 | E8: Chào hỏi & Lịch sự | F8: Câu hỏi | G8: Câu hỏi rút gọn với Dativ | H8: Und Ihnen? | I8: [ʔʊnt ˈʔiːnən] | J8: Còn ông/bà thì sao? | K8: und = và | R8: =COUNT($M8:$Q8) -> 0 | S8: =IF($L8="","",IF($R8>=5,"",MAX($L8:$Q8)+CHOOSE($R8+1,SETTINGS!$C$9,SETTINGS!$C$10,SETTINGS!$C$11,SETTINGS!$C$12,SETTINGS!$C$13))) | T8: =IF($H8="","(chưa có nội dung)",IF($L8="",IF($C8<TODAY(),"⚠ TRỄ HỌC",IF($C8=TODAY(),"★ HỌC HÔM NAY","• Chưa tới")),IF($R8>=5,"✔ MASTER",IF($S8<TODAY(),"⚠ TRỄ ÔN",IF($S8=TODAY(),"◆ ÔN HÔM NAY","✔ Đúng tiến độ"))))) -> ⚠ TRỄ HỌC | U8: =IF($H8="","",$R8/5) -> 0
A9: S0007 | B9: 1 | C9: =SETTINGS!$C$3+$B9-1 -> 46300 | D9: A1 | E9: Chào hỏi & Lịch sự | F9: Câu cảm thán | G9: zu + Infinitiv | H9: Guten Abend, schön Sie zu sehen. | I9: [ˈɡuːtən ˈʔaːbənt, ˈʃøːn ziː tsuː ˈzeːən] | J9: Chào buổi tối, rất vui được gặp ông/bà. | K9: der Abend = buổi tối; schön = đẹp/vui; sehen = nhìn thấy | R9: =COUNT($M9:$Q9) -> 0 | S9: =IF($L9="","",IF($R9>=5,"",MAX($L9:$Q9)+CHOOSE($R9+1,SETTINGS!$C$9,SETTINGS!$C$10,SETTINGS!$C$11,SETTINGS!$C$12,SETTINGS!$C$13))) | T9: =IF($H9="","(chưa có nội dung)",IF($L9="",IF($C9<TODAY(),"⚠ TRỄ HỌC",IF($C9=TODAY(),"★ HỌC HÔM NAY","• Chưa tới")),IF($R9>=5,"✔ MASTER",IF($S9<TODAY(),"⚠ TRỄ ÔN",IF($S9=TODAY(),"◆ ÔN HÔM NAY","✔ Đúng tiến độ"))))) -> ⚠ TRỄ HỌC | U9: =IF($H9="","",$R9/5) -> 0
A10: S0008 | B10: 1 | C10: =SETTINGS!$C$3+$B10-1 -> 46300 | D10: A1 | E10: Chào hỏi & Lịch sự | F10: Mệnh lệnh | G10: Imperativ với du (bỏ -st) | H10: Gute Nacht, schlaf gut! | I10: [ˈɡuːtə ˈnaxt, ˈʃlaːf ˈɡuːt] | J10: Chúc ngủ ngon, ngủ ngon nhé! | K10: die Nacht = đêm; schlafen = ngủ | R10: =COUNT($M10:$Q10) -> 0 | S10: =IF($L10="","",IF($R10>=5,"",MAX($L10:$Q10)+CHOOSE($R10+1,SETTINGS!$C$9,SETTINGS!$C$10,SETTINGS!$C$11,SETTINGS!$C$12,SETTINGS!$C$13))) | T10: =IF($H10="","(chưa có nội dung)",IF($L10="",IF($C10<TODAY(),"⚠ TRỄ HỌC",IF($C10=TODAY(),"★ HỌC HÔM NAY","• Chưa tới")),IF($R10>=5,"✔ MASTER",IF($S10<TODAY(),"⚠ TRỄ ÔN",IF($S10=TODAY(),"◆ ÔN HÔM NAY","✔ Đúng tiến độ"))))) -> ⚠ TRỄ HỌC | U10: =IF($H10="","",$R10/5) -> 0
A11: S0009 | B11: 1 | C11: =SETTINGS!$C$3+$B11-1 -> 46300 | D11: A1 | E11: Chào hỏi & Lịch sự | F11: Câu cảm thán | G11: Cụm cố định | H11: Auf Wiedersehen! | I11: [ʔaʊf viːdɐˈzeːən] | J11: Tạm biệt! (trang trọng) | K11: wieder = lại | R11: =COUNT($M11:$Q11) -> 0 | S11: =IF($L11="","",IF($R11>=5,"",MAX($L11:$Q11)+CHOOSE($R11+1,SETTINGS!$C$9,SETTINGS!$C$10,SETTINGS!$C$11,SETTINGS!$C$12,SETTINGS!$C$13))) | T11: =IF($H11="","(chưa có nội dung)",IF($L11="",IF($C11<TODAY(),"⚠ TRỄ HỌC",IF($C11=TODAY(),"★ HỌC HÔM NAY","• Chưa tới")),IF($R11>=5,"✔ MASTER",IF($S11<TODAY(),"⚠ TRỄ ÔN",IF($S11=TODAY(),"◆ ÔN HÔM NAY","✔ Đúng tiến độ"))))) -> ⚠ TRỄ HỌC | U11: =IF($H11="","",$R11/5) -> 0
A12: S0010 | B12: 1 | C12: =SETTINGS!$C$3+$B12-1 -> 46300 | D12: A1 | E12: Chào hỏi & Lịch sự | F12: Câu cảm thán | G12: bis + thời gian | H12: Tschüss, bis morgen! | I12: [ˈtʃys, bɪs ˈmɔʁɡən] | J12: Tạm biệt, hẹn mai nhé! | K12: bis = cho đến; morgen = ngày mai | R12: =COUNT($M12:$Q12) -> 0 | S12: =IF($L12="","",IF($R12>=5,"",MAX($L12:$Q12)+CHOOSE($R12+1,SETTINGS!$C$9,SETTINGS!$C$10,SETTINGS!$C$11,SETTINGS!$C$12,SETTINGS!$C$13))) | T12: =IF($H12="","(chưa có nội dung)",IF($L12="",IF($C12<TODAY(),"⚠ TRỄ HỌC",IF($C12=TODAY(),"★ HỌC HÔM NAY","• Chưa tới")),IF($R12>=5,"✔ MASTER",IF($S12<TODAY(),"⚠ TRỄ ÔN",IF($S12=TODAY(),"◆ ÔN HÔM NAY","✔ Đúng tiến độ"))))) -> ⚠ TRỄ HỌC | U12: =IF($H12="","",$R12/5) -> 0
A13: S0011 | B13: 1 | C13: =SETTINGS!$C$3+$B13-1 -> 46300 | D13: A1 | E13: Chào hỏi & Lịch sự | F13: Câu cảm thán | G13: bis + trạng từ thời gian | H13: Bis später! | I13: [bɪs ˈʃpɛːtɐ] | J13: Hẹn gặp lại sau! | K13: später = sau này | R13: =COUNT($M13:$Q13) -> 0 | S13: =IF($L13="","",IF($R13>=5,"",MAX($L13:$Q13)+CHOOSE($R13+1,SETTINGS!$C$9,SETTINGS!$C$10,SETTINGS!$C$11,SETTINGS!$C$12,SETTINGS!$C$13))) | T13: =IF($H13="","(chưa có nội dung)",IF($L13="",IF($C13<TODAY(),"⚠ TRỄ HỌC",IF($C13=TODAY(),"★ HỌC HÔM NAY","• Chưa tới")),IF($R13>=5,"✔ MASTER",IF($S13<TODAY(),"⚠ TRỄ ÔN",IF($S13=TODAY(),"◆ ÔN HÔM NAY","✔ Đúng tiến độ"))))) -> ⚠ TRỄ HỌC | U13: =IF($H13="","",$R13/5) -> 0
A14: S0012 | B14: 1 | C14: =SETTINGS!$C$3+$B14-1 -> 46300 | D14: A1 | E14: Chào hỏi & Lịch sự | F14: Câu cảm thán | G14: Cụm cố định | H14: Bis bald! | I14: [bɪs ˈbalt] | J14: Hẹn sớm gặp lại! | K14: bald = sớm | R14: =COUNT($M14:$Q14) -> 0 | S14: =IF($L14="","",IF($R14>=5,"",MAX($L14:$Q14)+CHOOSE($R14+1,SETTINGS!$C$9,SETTINGS!$C$10,SETTINGS!$C$11,SETTINGS!$C$12,SETTINGS!$C$13))) | T14: =IF($H14="","(chưa có nội dung)",IF($L14="",IF($C14<TODAY(),"⚠ TRỄ HỌC",IF($C14=TODAY(),"★ HỌC HÔM NAY","• Chưa tới")),IF($R14>=5,"✔ MASTER",IF($S14<TODAY(),"⚠ TRỄ ÔN",IF($S14=TODAY(),"◆ ÔN HÔM NAY","✔ Đúng tiến độ"))))) -> ⚠ TRỄ HỌC | U14: =IF($H14="","",$R14/5) -> 0
... A1802: S1800 | B1802: 90 | C1802: =SETTINGS!$C$3+$B1802-1 -> 46389 | D1802: B2 | E1802: Luyện thi B2 (Redemittel) | F1802: Mẫu câu thi | G1802: aufschlussreich = sáng tỏ | H1802: Vielen Dank, das war sehr aufschlussreich. | I1802: [ˈfiːlən ˈdaŋk, das vaːɐ̯ ˈzeːɐ̯ ˈʔaʊfˌʃlʊsʁaɪç] | J1802: Cảm ơn nhiều, điều đó rất sáng tỏ. | K1802: aufschlussreich = làm sáng tỏ | R1802: =COUNT($M1802:$Q1802) -> 0 | S1802: =IF($L1802="","",IF($R1802>=5,"",MAX($L1802:$Q1802)+CHOOSE($R1802+1,SETTINGS!$C$9,SETTINGS!$C$10,SETTINGS!$C$11,SETTINGS!$C$12,SETTINGS!$C$13))) | T1802: =IF($H1802="","(chưa có nội dung)",IF($L1802="",IF($C1802<TODAY(),"⚠ TRỄ HỌC",IF($C1802=TODAY(),"★ HỌC HÔM NAY","• Chưa tới")),IF($R1802>=5,"✔ MASTER",IF($S1802<TODAY(),"⚠ TRỄ ÔN",IF($S1802=TODAY(),"◆ ÔN HÔM NAY","✔ Đúng tiến độ"))))) -> • Chưa tới | U1802: =IF($H1802="","",$R1802/5) -> 0

Sheet VOCAB
A1: TỪ VỰNG CHÚ THÍCH THEO TỪNG CÂU | dùng AutoFilter để lọc theo loại từ, chủ đề, cấp độ
A2: STT | B2: Từ / Cụm từ (Đức) | C2: Nghĩa tiếng Việt | D2: Loại từ | E2: Giống (Artikel) | F2: ID câu | G2: Ngày thứ | H2: Cấp độ | I2: Chủ đề | J2: Câu chứa từ | K2: Nghĩa của câu | L2: Số lần xuất hiện | M2: Trạng thái câu
A3: 1 | B3: der Morgen | C3: buổi sáng | D3: Danh từ | E3: Đực (der) | F3: S0001 | G3: 1 | H3: A1 | I3: Chào hỏi & Lịch sự | J3: Guten Morgen! | K3: Chào buổi sáng! | L3: =COUNTIF($B$3:$B$2205,$B3) -> 1 | M3: =IFERROR(INDEX(SENTENCES!$T$3:$T$1802,MATCH($F3,SENTENCES!$A$3:$A$1802,0)),"") -> ⚠ TRỄ HỌC
A4: 2 | B4: gut | C4: tốt | D4: Tính từ / Trạng từ / Khác | F4: S0001 | G4: 1 | H4: A1 | I4: Chào hỏi & Lịch sự | J4: Guten Morgen! | K4: Chào buổi sáng! | L4: =COUNTIF($B$3:$B$2205,$B4) -> 1 | M4: =IFERROR(INDEX(SENTENCES!$T$3:$T$1802,MATCH($F4,SENTENCES!$A$3:$A$1802,0)),"") -> ⚠ TRỄ HỌC
A5: 3 | B5: der Tag | C5: ngày | D5: Danh từ | E5: Đực (der) | F5: S0002 | G5: 1 | H5: A1 | I5: Chào hỏi & Lịch sự | J5: Guten Tag, wie geht es Ihnen? | K5: Chào ông/bà, ông/bà khỏe không? | L5: =COUNTIF($B$3:$B$2205,$B5) -> 1 | M5: =IFERROR(INDEX(SENTENCES!$T$3:$T$1802,MATCH($F5,SENTENCES!$A$3:$A$1802,0)),"") -> ⚠ TRỄ HỌC
A6: 4 | B6: gehen | C6: đi/diễn ra | D6: Động từ | F6: S0002 | G6: 1 | H6: A1 | I6: Chào hỏi & Lịch sự | J6: Guten Tag, wie geht es Ihnen? | K6: Chào ông/bà, ông/bà khỏe không? | L6: =COUNTIF($B$3:$B$2205,$B6) -> 2 | M6: =IFERROR(INDEX(SENTENCES!$T$3:$T$1802,MATCH($F6,SENTENCES!$A$3:$A$1802,0)),"") -> ⚠ TRỄ HỌC
A7: 5 | B7: dir | C7: với bạn (Dativ) | D7: Tính từ / Trạng từ / Khác | F7: S0003 | G7: 1 | H7: A1 | I7: Chào hỏi & Lịch sự | J7: Hallo, wie geht's dir? | K7: Chào bạn, bạn khỏe không? | L7: =COUNTIF($B$3:$B$2205,$B7) -> 1 | M7: =IFERROR(INDEX(SENTENCES!$T$3:$T$1802,MATCH($F7,SENTENCES!$A$3:$A$1802,0)),"") -> ⚠ TRỄ HỌC
A8: 6 | B8: mir | C8: với tôi (Dativ) | D8: Tính từ / Trạng từ / Khác | F8: S0004 | G8: 1 | H8: A1 | I8: Chào hỏi & Lịch sự | J8: Mir geht es gut, danke. | K8: Tôi khỏe, cảm ơn. | L8: =COUNTIF($B$3:$B$2205,$B8) -> 1 | M8: =IFERROR(INDEX(SENTENCES!$T$3:$T$1802,MATCH($F8,SENTENCES!$A$3:$A$1802,0)),"") -> ⚠ TRỄ HỌC
A9: 7 | B9: danke | C9: cảm ơn | D9: Tính từ / Trạng từ / Khác | F9: S0004 | G9: 1 | H9: A1 | I9: Chào hỏi & Lịch sự | J9: Mir geht es gut, danke. | K9: Tôi khỏe, cảm ơn. | L9: =COUNTIF($B$3:$B$2205,$B9) -> 1 | M9: =IFERROR(INDEX(SENTENCES!$T$3:$T$1802,MATCH($F9,SENTENCES!$A$3:$A$1802,0)),"") -> ⚠ TRỄ HỌC
A10: 8 | B10: nicht | C10: không | D10: Tính từ / Trạng từ / Khác | F10: S0005 | G10: 1 | H10: A1 | I10: Chào hỏi & Lịch sự | J10: Es geht mir nicht so gut. | K10: Tôi không được khỏe lắm. | L10: =COUNTIF($B$3:$B$2205,$B10) -> 1 | M10: =IFERROR(INDEX(SENTENCES!$T$3:$T$1802,MATCH($F10,SENTENCES!$A$3:$A$1802,0)),"") -> ⚠ TRỄ HỌC
A11: 9 | B11: so | C11: như thế | D11: Tính từ / Trạng từ / Khác | F11: S0005 | G11: 1 | H11: A1 | I11: Chào hỏi & Lịch sự | J11: Es geht mir nicht so gut. | K11: Tôi không được khỏe lắm. | L11: =COUNTIF($B$3:$B$2205,$B11) -> 1 | M11: =IFERROR(INDEX(SENTENCES!$T$3:$T$1802,MATCH($F11,SENTENCES!$A$3:$A$1802,0)),"") -> ⚠ TRỄ HỌC
A12: 10 | B12: und | C12: và | D12: Tính từ / Trạng từ / Khác | F12: S0006 | G12: 1 | H12: A1 | I12: Chào hỏi & Lịch sự | J12: Und Ihnen? | K12: Còn ông/bà thì sao? | L12: =COUNTIF($B$3:$B$2205,$B12) -> 1 | M12: =IFERROR(INDEX(SENTENCES!$T$3:$T$1802,MATCH($F12,SENTENCES!$A$3:$A$1802,0)),"") -> ⚠ TRỄ HỌC
A13: 11 | B13: der Abend | C13: buổi tối | D13: Danh từ | E13: Đực (der) | F13: S0007 | G13: 1 | H13: A1 | I13: Chào hỏi & Lịch sự | J13: Guten Abend, schön Sie zu sehen. | K13: Chào buổi tối, rất vui được gặp ông/bà. | L13: =COUNTIF($B$3:$B$2205,$B13) -> 1 | M13: =IFERROR(INDEX(SENTENCES!$T$3:$T$1802,MATCH($F13,SENTENCES!$A$3:$A$1802,0)),"") -> ⚠ TRỄ HỌC
A14: 12 | B14: schön | C14: đẹp/vui | D14: Tính từ / Trạng từ / Khác | F14: S0007 | G14: 1 | H14: A1 | I14: Chào hỏi & Lịch sự | J14: Guten Abend, schön Sie zu sehen. | K14: Chào buổi tối, rất vui được gặp ông/bà. | L14: =COUNTIF($B$3:$B$2205,$B14) -> 3 | M14: =IFERROR(INDEX(SENTENCES!$T$3:$T$1802,MATCH($F14,SENTENCES!$A$3:$A$1802,0)),"") -> ⚠ TRỄ HỌC
A15: 13 | B15: sehen | C15: nhìn thấy | D15: Động từ | F15: S0007 | G15: 1 | H15: A1 | I15: Chào hỏi & Lịch sự | J15: Guten Abend, schön Sie zu sehen. | K15: Chào buổi tối, rất vui được gặp ông/bà. | L15: =COUNTIF($B$3:$B$2205,$B15) -> 2 | M15: =IFERROR(INDEX(SENTENCES!$T$3:$T$1802,MATCH($F15,SENTENCES!$A$3:$A$1802,0)),"") -> ⚠ TRỄ HỌC
A16: 14 | B16: die Nacht | C16: đêm | D16: Danh từ | E16: Cái (die) | F16: S0008 | G16: 1 | H16: A1 | I16: Chào hỏi & Lịch sự | J16: Gute Nacht, schlaf gut! | K16: Chúc ngủ ngon, ngủ ngon nhé! | L16: =COUNTIF($B$3:$B$2205,$B16) -> 1 | M16: =IFERROR(INDEX(SENTENCES!$T$3:$T$1802,MATCH($F16,SENTENCES!$A$3:$A$1802,0)),"") -> ⚠ TRỄ HỌC
A17: 15 | B17: schlafen | C17: ngủ | D17: Động từ | F17: S0008 | G17: 1 | H17: A1 | I17: Chào hỏi & Lịch sự | J17: Gute Nacht, schlaf gut! | K17: Chúc ngủ ngon, ngủ ngon nhé! | L17: =COUNTIF($B$3:$B$2205,$B17) -> 1 | M17: =IFERROR(INDEX(SENTENCES!$T$3:$T$1802,MATCH($F17,SENTENCES!$A$3:$A$1802,0)),"") -> ⚠ TRỄ HỌC
A18: 16 | B18: wieder | C18: lại | D18: Tính từ / Trạng từ / Khác | F18: S0009 | G18: 1 | H18: A1 | I18: Chào hỏi & Lịch sự | J18: Auf Wiedersehen! | K18: Tạm biệt! (trang trọng) | L18: =COUNTIF($B$3:$B$2205,$B18) -> 2 | M18: =IFERROR(INDEX(SENTENCES!$T$3:$T$1802,MATCH($F18,SENTENCES!$A$3:$A$1802,0)),"") -> ⚠ TRỄ HỌC
A19: 17 | B19: bis | C19: cho đến | D19: Tính từ / Trạng từ / Khác | F19: S0010 | G19: 1 | H19: A1 | I19: Chào hỏi & Lịch sự | J19: Tschüss, bis morgen! | K19: Tạm biệt, hẹn mai nhé! | L19: =COUNTIF($B$3:$B$2205,$B19) -> 2 | M19: =IFERROR(INDEX(SENTENCES!$T$3:$T$1802,MATCH($F19,SENTENCES!$A$3:$A$1802,0)),"") -> ⚠ TRỄ HỌC
A20: 18 | B20: morgen | C20: ngày mai | D20: Động từ | F20: S0010 | G20: 1 | H20: A1 | I20: Chào hỏi & Lịch sự | J20: Tschüss, bis morgen! | K20: Tạm biệt, hẹn mai nhé! | L20: =COUNTIF($B$3:$B$2205,$B20) -> 1 | M20: =IFERROR(INDEX(SENTENCES!$T$3:$T$1802,MATCH($F20,SENTENCES!$A$3:$A$1802,0)),"") -> ⚠ TRỄ HỌC
A21: 19 | B21: später | C21: sau này | D21: Tính từ / Trạng từ / Khác | F21: S0011 | G21: 1 | H21: A1 | I21: Chào hỏi & Lịch sự | J21: Bis später! | K21: Hẹn gặp lại sau! | L21: =COUNTIF($B$3:$B$2205,$B21) -> 2 | M21: =IFERROR(INDEX(SENTENCES!$T$3:$T$1802,MATCH($F21,SENTENCES!$A$3:$A$1802,0)),"") -> ⚠ TRỄ HỌC
A22: 20 | B22: bald | C22: sớm | D22: Tính từ / Trạng từ / Khác | F22: S0012 | G22: 1 | H22: A1 | I22: Chào hỏi & Lịch sự | J22: Bis bald! | K22: Hẹn sớm gặp lại! | L22: =COUNTIF($B$3:$B$2205,$B22) -> 2 | M22: =IFERROR(INDEX(SENTENCES!$T$3:$T$1802,MATCH($F22,SENTENCES!$A$3:$A$1802,0)),"") -> ⚠ TRỄ HỌC
A23: 21 | B23: willkommen | C23: chào mừng | D23: Động từ | F23: S0013 | G23: 1 | H23: A1 | I23: Chào hỏi & Lịch sự | J23: Herzlich willkommen in Deutschland! | K23: Chào mừng đến nước Đức! | L23: =COUNTIF($B$3:$B$2205,$B23) -> 1 | M23: =IFERROR(INDEX(SENTENCES!$T$3:$T$1802,MATCH($F23,SENTENCES!$A$3:$A$1802,0)),"") -> ⚠ TRỄ HỌC
A24: 22 | B24: Deutschland | C24: nước Đức | D24: Danh từ (không rõ giống) | F24: S0013 | G24: 1 | H24: A1 | I24: Chào hỏi & Lịch sự | J24: Herzlich willkommen in Deutschland! | K24: Chào mừng đến nước Đức! | L24: =COUNTIF($B$3:$B$2205,$B24) -> 1 | M24: =IFERROR(INDEX(SENTENCES!$T$3:$T$1802,MATCH($F24,SENTENCES!$A$3:$A$1802,0)),"") -> ⚠ TRỄ HỌC
A25: 23 | B25: noch | C25: còn nữa | D25: Tính từ / Trạng từ / Khác | F25: S0014 | G25: 1 | H25: A1 | I25: Chào hỏi & Lịch sự | J25: Schönen Tag noch! | K25: Chúc một ngày tốt lành! | L25: =COUNTIF($B$3:$B$2205,$B25) -> 3 | M25: =IFERROR(INDEX(SENTENCES!$T$3:$T$1802,MATCH($F25,SENTENCES!$A$3:$A$1802,0)),"") -> ⚠ TRỄ HỌC
A26: 24 | B26: viel | C26: nhiều | D26: Tính từ / Trạng từ / Khác | F26: S0015 | G26: 1 | H26: A1 | I26: Chào hỏi & Lịch sự | J26: Vielen Dank für alles. | K26: Cảm ơn vì tất cả. | L26: =COUNTIF($B$3:$B$2205,$B26) -> 3 | M26: =IFERROR(INDEX(SENTENCES!$T$3:$T$1802,MATCH($F26,SENTENCES!$A$3:$A$1802,0)),"") -> ⚠ TRỄ HỌC
A27: 25 | B27: für | C27: cho/vì | D27: Tính từ / Trạng từ / Khác | F27: S0015 | G27: 1 | H27: A1 | I27: Chào hỏi & Lịch sự | J27: Vielen Dank für alles. | K27: Cảm ơn vì tất cả. | L27: =COUNTIF($B$3:$B$2205,$B27) -> 3 | M27: =IFERROR(INDEX(SENTENCES!$T$3:$T$1802,MATCH($F27,SENTENCES!$A$3:$A$1802,0)),"") -> ⚠ TRỄ HỌC
A28: 26 | B28: alles | C28: tất cả | D28: Tính từ / Trạng từ / Khác | F28: S0015 | G28: 1 | H28: A1 | I28: Chào hỏi & Lịch sự | J28: Vielen Dank für alles. | K28: Cảm ơn vì tất cả. | L28: =COUNTIF($B$3:$B$2205,$B28) -> 3 | M28: =IFERROR(INDEX(SENTENCES!$T$3:$T$1802,MATCH($F28,SENTENCES!$A$3:$A$1802,0)),"") -> ⚠ TRỄ HỌC
A29: 27 | B29: bitte | C29: xin mời/làm ơn | D29: Tính từ / Trạng từ / Khác | F29: S0016 | G29: 1 | H29: A1 | I29: Chào hỏi & Lịch sự | J29: Bitte schön. | K29: Không có gì. / Của bạn đây. | L29: =COUNTIF($B$3:$B$2205,$B29) -> 1 | M29: =IFERROR(INDEX(SENTENCES!$T$3:$T$1802,MATCH($F29,SENTENCES!$A$3:$A$1802,0)),"") -> ⚠ TRỄ HỌC
A30: 28 | B30: die Entschuldigung | C30: lời xin lỗi | D30: Danh từ | E30: Cái (die) | F30: S0017 | G30: 1 | H30: A1 | I30: Chào hỏi & Lịch sự | J30: Entschuldigung, darf ich etwas fragen? | K30: Xin lỗi, tôi hỏi một chút được không? | L30: =COUNTIF($B$3:$B$2205,$B30) -> 1 | M30: =IFERROR(INDEX(SENTENCES!$T$3:$T$1802,MATCH($F30,SENTENCES!$A$3:$A$1802,0)),"") -> ⚠ TRỄ HỌC
A31: 29 | B31: dürfen | C31: được phép | D31: Động từ | F31: S0017 | G31: 1 | H31: A1 | I31: Chào hỏi & Lịch sự | J31: Entschuldigung, darf ich etwas fragen? | K31: Xin lỗi, tôi hỏi một chút được không? | L31: =COUNTIF($B$3:$B$2205,$B31) -> 2 | M31: =IFERROR(INDEX(SENTENCES!$T$3:$T$1802,MATCH($F31,SENTENCES!$A$3:$A$1802,0)),"") -> ⚠ TRỄ HỌC
A32: 30 | B32: fragen | C32: hỏi | D32: Động từ | F32: S0017 | G32: 1 | H32: A1 | I32: Chào hỏi & Lịch sự | J32: Entschuldigung, darf ich etwas fragen? | K32: Xin lỗi, tôi hỏi một chút được không? | L32: =COUNTIF($B$3:$B$2205,$B32) -> 1 | M32: =IFERROR(INDEX(SENTENCES!$T$3:$T$1802,MATCH($F32,SENTENCES!$A$3:$A$1802,0)),"") -> ⚠ TRỄ HỌC
A33: 31 | B33: etwas | C33: một chút | D33: Tính từ / Trạng từ / Khác | F33: S0017 | G33: 1 | H33: A1 | I33: Chào hỏi & Lịch sự | J33: Entschuldigung, darf ich etwas fragen? | K33: Xin lỗi, tôi hỏi một chút được không? | L33: =COUNTIF($B$3:$B$2205,$B33) -> 3 | M33: =IFERROR(INDEX(SENTENCES!$T$3:$T$1802,MATCH($F33,SENTENCES!$A$3:$A$1802,0)),"") -> ⚠ TRỄ HỌC
A34: 32 | B34: leidtun | C34: làm ai tiếc | D34: Tính từ / Trạng từ / Khác | F34: S0018 | G34: 1 | H34: A1 | I34: Chào hỏi & Lịch sự | J34: Es tut mir leid. | K34: Tôi xin lỗi. / Tôi rất tiếc. | L34: =COUNTIF($B$3:$B$2205,$B34) -> 2 | M34: =IFERROR(INDEX(SENTENCES!$T$3:$T$1802,MATCH($F34,SENTENCES!$A$3:$A$1802,0)),"") -> ⚠ TRỄ HỌC
A35: 33 | B35: das Problem | C35: vấn đề | D35: Danh từ | E35: Trung (das) | F35: S0019 | G35: 1 | H35: A1 | I35: Chào hỏi & Lịch sự | J35: Kein Problem. | K35: Không vấn đề gì. | L35: =COUNTIF($B$3:$B$2205,$B35) -> 1 | M35: =IFERROR(INDEX(SENTENCES!$T$3:$T$1802,MATCH($F35,SENTENCES!$A$3:$A$1802,0)),"") -> ⚠ TRỄ HỌC
A36: 34 | B36: kein | C36: không có | D36: Tính từ / Trạng từ / Khác | F36: S0019 | G36: 1 | H36: A1 | I36: Chào hỏi & Lịch sự | J36: Kein Problem. | K36: Không vấn đề gì. | L36: =COUNTIF($B$3:$B$2205,$B36) -> 1 | M36: =IFERROR(INDEX(SENTENCES!$T$3:$T$1802,MATCH($F36,SENTENCES!$A$3:$A$1802,0)),"") -> ⚠ TRỄ HỌC
A37: 35 | B37: kennenlernen | C37: làm quen | D37: Động từ | F37: S0020 | G37: 1 | H37: A1 | I37: Chào hỏi & Lịch sự | J37: Freut mich, Sie kennenzulernen. | K37: Rất vui được làm quen với ông/bà. | L37: =COUNTIF($B$3:$B$2205,$B37) -> 2 | M37: =IFERROR(INDEX(SENTENCES!$T$3:$T$1802,MATCH($F37,SENTENCES!$A$3:$A$1802,0)),"") -> ⚠ TRỄ HỌC
A38: 36 | B38: sich freuen | C38: vui | D38: Động từ phản thân | F38: S0020 | G38: 1 | H38: A1 | I38: Chào hỏi & Lịch sự | J38: Freut mich, Sie kennenzulernen. | K38: Rất vui được làm quen với ông/bà. | L38: =COUNTIF($B$3:$B$2205,$B38) -> 2 | M38: =IFERROR(INDEX(SENTENCES!$T$3:$T$1802,MATCH($F38,SENTENCES!$A$3:$A$1802,0)),"") -> ⚠ TRỄ HỌC
A39: 37 | B39: heißen | C39: tên là | D39: Động từ | F39: S0021 | G39: 2 | H39: A1 | I39: Giới thiệu bản thân | J39: Ich heiße Minh. | K39: Tôi tên là Minh. | L39: =COUNTIF($B$3:$B$2205,$B39) -> 1 | M39: =IFERROR(INDEX(SENTENCES!$T$3:$T$1802,MATCH($F39,SENTENCES!$A$3:$A$1802,0)),"") -> ★ HỌC HÔM NAY
A40: 38 | B40: wie | C40: như thế nào | D40: Tính từ / Trạng từ / Khác | F40: S0022 | G40: 2 | H40: A1 | I40: Giới thiệu bản thân | J40: Wie heißen Sie? | K40: Ông/bà tên gì? | L40: =COUNTIF($B$3:$B$2205,$B40) -> 1 | M40: =IFERROR(INDEX(SENTENCES!$T$3:$T$1802,MATCH($F40,SENTENCES!$A$3:$A$1802,0)),"") -> ★ HỌC HÔM NAY
...

Sheet DAILY_LOG
A1: NHẬT KÝ 105 NGÀY (90 ngày kế hoạch + 15 ngày đệm) | toàn bộ tự đếm, không cần nhập tay
A2: Ngày thứ | B2: Ngày | C2: Thứ | D2: Kế hoạch lũy kế | E2: Câu MỚI học trong ngày | F2: Lượt ÔN trong ngày | G2: Tổng hoạt động | H2: Lũy kế đã học | I2: Câu còn nợ | J2: Số ngày trễ | K2: Trạng thái ngày | L2: Cảnh báo
A3: 1 | B3: =SETTINGS!$C$3+$A3-1 -> 46300 | C3: =CHOOSE(WEEKDAY($B3,2),"Thứ 2","Thứ 3","Thứ 4","Thứ 5","Thứ 6","Thứ 7","CN") -> Thứ 2 | D3: =MIN($A3*SETTINGS!$C$4,SETTINGS!$C$6) -> 20 | E3: =COUNTIF(SENTENCES!$L$3:$L$1802,$B3) -> 0 | F3: =COUNTIF(SENTENCES!$M$3:$Q$1802,$B3) -> 0 | G3: =$E3+$F3 -> 0 | H3: =COUNTIFS(SENTENCES!$L$3:$L$1802,"<="&$B3,SENTENCES!$L$3:$L$1802,">0") -> 0 | I3: =IF($B3>TODAY(),"",MAX(0,$D3-$H3)) -> 20 | J3: =IF($I3="","",ROUND($I3/SETTINGS!$C$4,1)) -> 1 | K3: =IF($B3>TODAY(),"",IF($E3>=SETTINGS!$C$4,"✔ Đủ chỉ tiêu",IF($E3>0,"⚠ Thiếu",IF($F3>0,"◆ Chỉ ôn","✖ Nghỉ / Miss")))) -> ✖ Nghỉ / Miss | L3: =IF($J3="","",IF($J3>SETTINGS!$C$7,"🔴 VƯỢT NGƯỠNG ĐỆM",IF($J3>3,"🟡 Cần học bù","🟢 Đang ổn"))) -> 🟢 Đang ổn
A4: 2 | B4: =SETTINGS!$C$3+$A4-1 -> 46301 | C4: =CHOOSE(WEEKDAY($B4,2),"Thứ 2","Thứ 3","Thứ 4","Thứ 5","Thứ 6","Thứ 7","CN") -> Thứ 3 | D4: =MIN($A4*SETTINGS!$C$4,SETTINGS!$C$6) -> 40 | E4: =COUNTIF(SENTENCES!$L$3:$L$1802,$B4) -> 0 | F4: =COUNTIF(SENTENCES!$M$3:$Q$1802,$B4) -> 0 | G4: =$E4+$F4 -> 0 | H4: =COUNTIFS(SENTENCES!$L$3:$L$1802,"<="&$B4,SENTENCES!$L$3:$L$1802,">0") -> 0 | I4: =IF($B4>TODAY(),"",MAX(0,$D4-$H4)) -> 40 | J4: =IF($I4="","",ROUND($I4/SETTINGS!$C$4,1)) -> 2 | K4: =IF($B4>TODAY(),"",IF($E4>=SETTINGS!$C$4,"✔ Đủ chỉ tiêu",IF($E4>0,"⚠ Thiếu",IF($F4>0,"◆ Chỉ ôn","✖ Nghỉ / Miss")))) -> ✖ Nghỉ / Miss | L4: =IF($J4="","",IF($J4>SETTINGS!$C$7,"🔴 VƯỢT NGƯỠNG ĐỆM",IF($J4>3,"🟡 Cần học bù","🟢 Đang ổn"))) -> 🟢 Đang ổn
A5: 3 | B5: =SETTINGS!$C$3+$A5-1 -> 46302 | C5: =CHOOSE(WEEKDAY($B5,2),"Thứ 2","Thứ 3","Thứ 4","Thứ 5","Thứ 6","Thứ 7","CN") -> Thứ 4 | D5: =MIN($A5*SETTINGS!$C$4,SETTINGS!$C$6) -> 60 | E5: =COUNTIF(SENTENCES!$L$3:$L$1802,$B5) -> 0 | F5: =COUNTIF(SENTENCES!$M$3:$Q$1802,$B5) -> 0 | G5: =$E5+$F5 -> 0 | H5: =COUNTIFS(SENTENCES!$L$3:$L$1802,"<="&$B5,SENTENCES!$L$3:$L$1802,">0") -> 0 | I5: =IF($B5>TODAY(),"",MAX(0,$D5-$H5)) | J5: =IF($I5="","",ROUND($I5/SETTINGS!$C$4,1)) | K5: =IF($B5>TODAY(),"",IF($E5>=SETTINGS!$C$4,"✔ Đủ chỉ tiêu",IF($E5>0,"⚠ Thiếu",IF($F5>0,"◆ Chỉ ôn","✖ Nghỉ / Miss")))) | L5: =IF($J5="","",IF($J5>SETTINGS!$C$7,"🔴 VƯỢT NGƯỠNG ĐỆM",IF($J5>3,"🟡 Cần học bù","🟢 Đang ổn")))
A6: 4 | B6: =SETTINGS!$C$3+$A6-1 -> 46303 | C6: =CHOOSE(WEEKDAY($B6,2),"Thứ 2","Thứ 3","Thứ 4","Thứ 5","Thứ 6","Thứ 7","CN") -> Thứ 5 | D6: =MIN($A6*SETTINGS!$C$4,SETTINGS!$C$6) -> 80 | E6: =COUNTIF(SENTENCES!$L$3:$L$1802,$B6) -> 0 | F6: =COUNTIF(SENTENCES!$M$3:$Q$1802,$B6) -> 0 | G6: =$E6+$F6 -> 0 | H6: =COUNTIFS(SENTENCES!$L$3:$L$1802,"<="&$B6,SENTENCES!$L$3:$L$1802,">0") -> 0 | I6: =IF($B6>TODAY(),"",MAX(0,$D6-$H6)) | J6: =IF($I6="","",ROUND($I6/SETTINGS!$C$4,1)) | K6: =IF($B6>TODAY(),"",IF($E6>=SETTINGS!$C$4,"✔ Đủ chỉ tiêu",IF($E6>0,"⚠ Thiếu",IF($F6>0,"◆ Chỉ ôn","✖ Nghỉ / Miss")))) | L6: =IF($J6="","",IF($J6>SETTINGS!$C$7,"🔴 VƯỢT NGƯỠNG ĐỆM",IF($J6>3,"🟡 Cần học bù","🟢 Đang ổn")))
A7: 5 | B7: =SETTINGS!$C$3+$A7-1 -> 46304 | C7: =CHOOSE(WEEKDAY($B7,2),"Thứ 2","Thứ 3","Thứ 4","Thứ 5","Thứ 6","Thứ 7","CN") -> Thứ 6 | D7: =MIN($A7*SETTINGS!$C$4,SETTINGS!$C$6) -> 100 | E7: =COUNTIF(SENTENCES!$L$3:$L$1802,$B7) -> 0 | F7: =COUNTIF(SENTENCES!$M$3:$Q$1802,$B7) -> 0 | G7: =$E7+$F7 -> 0 | H7: =COUNTIFS(SENTENCES!$L$3:$L$1802,"<="&$B7,SENTENCES!$L$3:$L$1802,">0") -> 0 | I7: =IF($B7>TODAY(),"",MAX(0,$D7-$H7)) | J7: =IF($I7="","",ROUND($I7/SETTINGS!$C$4,1)) | K7: =IF($B7>TODAY(),"",IF($E7>=SETTINGS!$C$4,"✔ Đủ chỉ tiêu",IF($E7>0,"⚠ Thiếu",IF($F7>0,"◆ Chỉ ôn","✖ Nghỉ / Miss")))) | L7: =IF($J7="","",IF($J7>SETTINGS!$C$7,"🔴 VƯỢT NGƯỠNG ĐỆM",IF($J7>3,"🟡 Cần học bù","🟢 Đang ổn")))
A8: 6 | B8: =SETTINGS!$C$3+$A8-1 -> 46305 | C8: =CHOOSE(WEEKDAY($B8,2),"Thứ 2","Thứ 3","Thứ 4","Thứ 5","Thứ 6","Thứ 7","CN") -> Thứ 7 | D8: =MIN($A8*SETTINGS!$C$4,SETTINGS!$C$6) -> 120 | E8: =COUNTIF(SENTENCES!$L$3:$L$1802,$B8) -> 0 | F8: =COUNTIF(SENTENCES!$M$3:$Q$1802,$B8) -> 0 | G8: =$E8+$F8 -> 0 | H8: =COUNTIFS(SENTENCES!$L$3:$L$1802,"<="&$B8,SENTENCES!$L$3:$L$1802,">0") -> 0 | I8: =IF($B8>TODAY(),"",MAX(0,$D8-$H8)) | J8: =IF($I8="","",ROUND($I8/SETTINGS!$C$4,1)) | K8: =IF($B8>TODAY(),"",IF($E8>=SETTINGS!$C$4,"✔ Đủ chỉ tiêu",IF($E8>0,"⚠ Thiếu",IF($F8>0,"◆ Chỉ ôn","✖ Nghỉ / Miss")))) | L8: =IF($J8="","",IF($J8>SETTINGS!$C$7,"🔴 VƯỢT NGƯỠNG ĐỆM",IF($J8>3,"🟡 Cần học bù","🟢 Đang ổn")))
A9: 7 | B9: =SETTINGS!$C$3+$A9-1 -> 46306 | C9: =CHOOSE(WEEKDAY($B9,2),"Thứ 2","Thứ 3","Thứ 4","Thứ 5","Thứ 6","Thứ 7","CN") -> CN | D9: =MIN($A9*SETTINGS!$C$4,SETTINGS!$C$6) -> 140 | E9: =COUNTIF(SENTENCES!$L$3:$L$1802,$B9) -> 0 | F9: =COUNTIF(SENTENCES!$M$3:$Q$1802,$B9) -> 0 | G9: =$E9+$F9 -> 0 | H9: =COUNTIFS(SENTENCES!$L$3:$L$1802,"<="&$B9,SENTENCES!$L$3:$L$1802,">0") -> 0 | I9: =IF($B9>TODAY(),"",MAX(0,$D9-$H9)) | J9: =IF($I9="","",ROUND($I9/SETTINGS!$C$4,1)) | K9: =IF($B9>TODAY(),"",IF($E9>=SETTINGS!$C$4,"✔ Đủ chỉ tiêu",IF($E9>0,"⚠ Thiếu",IF($F9>0,"◆ Chỉ ôn","✖ Nghỉ / Miss")))) | L9: =IF($J9="","",IF($J9>SETTINGS!$C$7,"🔴 VƯỢT NGƯỠNG ĐỆM",IF($J9>3,"🟡 Cần học bù","🟢 Đang ổn")))
A10: 8 | B10: =SETTINGS!$C$3+$A10-1 -> 46307 | C10: =CHOOSE(WEEKDAY($B10,2),"Thứ 2","Thứ 3","Thứ 4","Thứ 5","Thứ 6","Thứ 7","CN") -> Thứ 2 | D10: =MIN($A10*SETTINGS!$C$4,SETTINGS!$C$6) -> 160 | E10: =COUNTIF(SENTENCES!$L$3:$L$1802,$B10) -> 0 | F10: =COUNTIF(SENTENCES!$M$3:$Q$1802,$B10) -> 0 | G10: =$E10+$F10 -> 0 | H10: =COUNTIFS(SENTENCES!$L$3:$L$1802,"<="&$B10,SENTENCES!$L$3:$L$1802,">0") -> 0 | I10: =IF($B10>TODAY(),"",MAX(0,$D10-$H10)) | J10: =IF($I10="","",ROUND($I10/SETTINGS!$C$4,1)) | K10: =IF($B10>TODAY(),"",IF($E10>=SETTINGS!$C$4,"✔ Đủ chỉ tiêu",IF($E10>0,"⚠ Thiếu",IF($F10>0,"◆ Chỉ ôn","✖ Nghỉ / Miss")))) | L10: =IF($J10="","",IF($J10>SETTINGS!$C$7,"🔴 VƯỢT NGƯỠNG ĐỆM",IF($J10>3,"🟡 Cần học bù","🟢 Đang ổn")))
A11: 9 | B11: =SETTINGS!$C$3+$A11-1 -> 46308 | C11: =CHOOSE(WEEKDAY($B11,2),"Thứ 2","Thứ 3","Thứ 4","Thứ 5","Thứ 6","Thứ 7","CN") -> Thứ 3 | D11: =MIN($A11*SETTINGS!$C$4,SETTINGS!$C$6) -> 180 | E11: =COUNTIF(SENTENCES!$L$3:$L$1802,$B11) -> 0 | F11: =COUNTIF(SENTENCES!$M$3:$Q$1802,$B11) -> 0 | G11: =$E11+$F11 -> 0 | H11: =COUNTIFS(SENTENCES!$L$3:$L$1802,"<="&$B11,SENTENCES!$L$3:$L$1802,">0") -> 0 | I11: =IF($B11>TODAY(),"",MAX(0,$D11-$H11)) | J11: =IF($I11="","",ROUND($I11/SETTINGS!$C$4,1)) | K11: =IF($B11>TODAY(),"",IF($E11>=SETTINGS!$C$4,"✔ Đủ chỉ tiêu",IF($E11>0,"⚠ Thiếu",IF($F11>0,"◆ Chỉ ôn","✖ Nghỉ / Miss")))) | L11: =IF($J11="","",IF($J11>SETTINGS!$C$7,"🔴 VƯỢT NGƯỠNG ĐỆM",IF($J11>3,"🟡 Cần học bù","🟢 Đang ổn")))
A12: 10 | B12: =SETTINGS!$C$3+$A12-1 -> 46309 | C12: =CHOOSE(WEEKDAY($B12,2),"Thứ 2","Thứ 3","Thứ 4","Thứ 5","Thứ 6","Thứ 7","CN") -> Thứ 4 | D12: =MIN($A12*SETTINGS!$C$4,SETTINGS!$C$6) -> 200 | E12: =COUNTIF(SENTENCES!$L$3:$L$1802,$B12) -> 0 | F12: =COUNTIF(SENTENCES!$M$3:$Q$1802,$B12) -> 0 | G12: =$E12+$F12 -> 0 | H12: =COUNTIFS(SENTENCES!$L$3:$L$1802,"<="&$B12,SENTENCES!$L$3:$L$1802,">0") -> 0 | I12: =IF($B12>TODAY(),"",MAX(0,$D12-$H12)) | J12: =IF($I12="","",ROUND($I12/SETTINGS!$C$4,1)) | K12: =IF($B12>TODAY(),"",IF($E12>=SETTINGS!$C$4,"✔ Đủ chỉ tiêu",IF($E12>0,"⚠ Thiếu",IF($F12>0,"◆ Chỉ ôn","✖ Nghỉ / Miss")))) | L12: =IF($J12="","",IF($J12>SETTINGS!$C$7,"🔴 VƯỢT NGƯỠNG ĐỆM",IF($J12>3,"🟡 Cần học bù","🟢 Đang ổn")))
A13: 11 | B13: =SETTINGS!$C$3+$A13-1 -> 46310 | C13: =CHOOSE(WEEKDAY($B13,2),"Thứ 2","Thứ 3","Thứ 4","Thứ 5","Thứ 6","Thứ 7","CN") -> Thứ 5 | D13: =MIN($A13*SETTINGS!$C$4,SETTINGS!$C$6) -> 220 | E13: =COUNTIF(SENTENCES!$L$3:$L$1802,$B13) -> 0 | F13: =COUNTIF(SENTENCES!$M$3:$Q$1802,$B13) -> 0 | G13: =$E13+$F13 -> 0 | H13: =COUNTIFS(SENTENCES!$L$3:$L$1802,"<="&$B13,SENTENCES!$L$3:$L$1802,">0") -> 0 | I13: =IF($B13>TODAY(),"",MAX(0,$D13-$H13)) | J13: =IF($I13="","",ROUND($I13/SETTINGS!$C$4,1)) | K13: =IF($B13>TODAY(),"",IF($E13>=SETTINGS!$C$4,"✔ Đủ chỉ tiêu",IF($E13>0,"⚠ Thiếu",IF($F13>0,"◆ Chỉ ôn","✖ Nghỉ / Miss")))) | L13: =IF($J13="","",IF($J13>SETTINGS!$C$7,"🔴 VƯỢT NGƯỠNG ĐỆM",IF($J13>3,"🟡 Cần học bù","🟢 Đang ổn")))
A14: 12 | B14: =SETTINGS!$C$3+$A14-1 -> 46311 | C14: =CHOOSE(WEEKDAY($B14,2),"Thứ 2","Thứ 3","Thứ 4","Thứ 5","Thứ 6","Thứ 7","CN") -> Thứ 6 | D14: =MIN($A14*SETTINGS!$C$4,SETTINGS!$C$6) -> 240 | E14: =COUNTIF(SENTENCES!$L$3:$L$1802,$B14) -> 0 | F14: =COUNTIF(SENTENCES!$M$3:$Q$1802,$B14) -> 0 | G14: =$E14+$F14 -> 0 | H14: =COUNTIFS(SENTENCES!$L$3:$L$1802,"<="&$B14,SENTENCES!$L$3:$L$1802,">0") -> 0 | I14: =IF($B14>TODAY(),"",MAX(0,$D14-$H14)) | J14: =IF($I14="","",ROUND($I14/SETTINGS!$C$4,1)) | K14: =IF($B14>TODAY(),"",IF($E14>=SETTINGS!$C$4,"✔ Đủ chỉ tiêu",IF($E14>0,"⚠ Thiếu",IF($F14>0,"◆ Chỉ ôn","✖ Nghỉ / Miss")))) | L14: =IF($J14="","",IF($J14>SETTINGS!$C$7,"🔴 VƯỢT NGƯỠNG ĐỆM",IF($J14>3,"🟡 Cần học bù","🟢 Đang ổn")))
... A107: 105 | B107: =SETTINGS!$C$3+$A107-1 -> 46404 | C107: =CHOOSE(WEEKDAY($B107,2),"Thứ 2","Thứ 3","Thứ 4","Thứ 5","Thứ 6","Thứ 7","CN") -> CN | D107: =MIN($A107*SETTINGS!$C$4,SETTINGS!$C$6) -> 1800 | E107: =COUNTIF(SENTENCES!$L$3:$L$1802,$B107) -> 0 | F107: =COUNTIF(SENTENCES!$M$3:$Q$1802,$B107) -> 0 | G107: =$E107+$F107 -> 0 | H107: =COUNTIFS(SENTENCES!$L$3:$L$1802,"<="&$B107,SENTENCES!$L$3:$L$1802,">0") -> 0 | I107: =IF($B107>TODAY(),"",MAX(0,$D107-$H107)) | J107: =IF($I107="","",ROUND($I107/SETTINGS!$C$4,1)) | K107: =IF($B107>TODAY(),"",IF($E107>=SETTINGS!$C$4,"✔ Đủ chỉ tiêu",IF($E107>0,"⚠ Thiếu",IF($F107>0,"◆ Chỉ ôn","✖ Nghỉ / Miss")))) | L107: =IF($J107="","",IF($J107>SETTINGS!$C$7,"🔴 VƯỢT NGƯỠNG ĐỆM",IF($J107>3,"🟡 Cần học bù","🟢 Đang ổn")))
